Workbook

Sheet 실습안내
B2: 1·2일차 · 민원 대장 정리(완성)
B4: 실습 목표 · 지저분한 민원 대장을 분석 가능한 데이터로 만들기
B5: 교재 연계 · 1장 Section 02 (데이터 편집), Section 01 (작업 필수 기능), 2장 Section 05 (텍스트·날짜 함수)
B6: 데이터 · 전부 가상 데이터입니다. 이름·연락처·주소는 실제 인물과 무관합니다.
B7: 진행 순서
B8: (1일차) 1) [데이터]→[중복된 항목 제거]로 접수번호 중복 행 제거 (몇 건이 지워지는지 확인)
B9: 2) J열: 접수일이 날짜/글자 혼재 → 모두 진짜 날짜로 (직접 수식 → AI 프롬프트 → 결과 비교)
B10: 3) K열 연락처 010-0000-0000 통일, L열 주소에서 '구'만 추출, M열 부서명 공백 통일, N열 상태값 공백 제거
B11: (2일차) 4) O열 경과(처리)일수, P열 14일 초과 건 표시 후 조건부 서식으로 빨간색 강조
B12: 5) 설정 시트의 기준일을 바꾸면 결과가 어떻게 변하는지 확인
B13: AI 활용 지점
B14: · 3)의 주소 분리는 '직접 수식'과 'AI가 만든 수식(TEXTSPLIT 등)'을 모두 시도해 보고, 내 엑셀 버전에서 되는 것을 고릅니다.
... B17: 중복 제거 후 행 수 72건 / 기한초과(처리중 & 14일 초과)·지연처리 건수는 P열 필터로 확인 (설정 기준일 2026-10-31)

Sheet 민원대장
A1: 접수번호 | B1: 접수일 | C1: 민원인 | D1: 연락처 | E1: 주소 | F1: 담당부서 | G1: 민원내용 | H1: 처리상태 | I1: 처리완료일 | J1: 정제_접수일 | K1: 정제_연락처 | L1: 정제_구 | M1: 정제_부서 | N1: 정제_상태 | O1: 경과(처리)일수 | P1: 기한초과
A2: 2026-0001 | B2: 46315 | C2: 서현우 | D2: 01044862807 | E2: 대구광역시 수성구 지산동 12-27 | F2: 교통행정과 | G2: 버스노선 조정 건의 | H2: 완료 | I2: 46316 | J2: =IF(ISNUMBER(B2),B2,DATE(VALUE(LEFT(B2,4)),VALUE(MID(B2,6,2)),VALUE(RIGHT(B2,2)))) | K2: =LEFT(SUBSTITUTE(SUBSTITUTE(D2,"-","")," ",""),3)&"-"&MID(SUBSTITUTE(SUBSTITUTE(D2,"-","")," ",""),4,4)&"-"&RIGHT(SUBSTITUTE(SUBSTITUTE(D2,"-","")," ",""),4) | L2: =TRIM(MID(SUBSTITUTE(TRIM(E2)," ",REPT(" ",50)),51,50)) | M2: =SUBSTITUTE(F2," ","") | N2: =TRIM(H2) | O2: =IF(I2="",설정!$B$2-J2,I2-J2) | P2: =IF(O2>14,IF(N2="처리중","기한초과","지연처리"),"")
A3: 2026-0009 | B3: 2026.10.10 | C3: 정소율 | D3: 01077949368 | E3: 대구광역시 북구 만촌동 589-25 | F3: 도로과 | G3: 도로 파손(포트홀) 신고 | H3: 처리중 | J3: =IF(ISNUMBER(B3),B3,DATE(VALUE(LEFT(B3,4)),VALUE(MID(B3,6,2)),VALUE(RIGHT(B3,2)))) | K3: =LEFT(SUBSTITUTE(SUBSTITUTE(D3,"-","")," ",""),3)&"-"&MID(SUBSTITUTE(SUBSTITUTE(D3,"-","")," ",""),4,4)&"-"&RIGHT(SUBSTITUTE(SUBSTITUTE(D3,"-","")," ",""),4) | L3: =TRIM(MID(SUBSTITUTE(TRIM(E3)," ",REPT(" ",50)),51,50)) | M3: =SUBSTITUTE(F3," ","") | N3: =TRIM(H3) | O3: =IF(I3="",설정!$B$2-J3,I3-J3) | P3: =IF(O3>14,IF(N3="처리중","기한초과","지연처리"),"")
A4: 2026-0002 | B4: 2026.09.23 | C4: 임민준 | D4: 01075686986 | E4: 대구광역시 동구 신암동 295-15 | F4: 건축과 | G4: 건축허가 처리 문의 | H4: 이관 | I4: 46305 | J4: =IF(ISNUMBER(B4),B4,DATE(VALUE(LEFT(B4,4)),VALUE(MID(B4,6,2)),VALUE(RIGHT(B4,2)))) | K4: =LEFT(SUBSTITUTE(SUBSTITUTE(D4,"-","")," ",""),3)&"-"&MID(SUBSTITUTE(SUBSTITUTE(D4,"-","")," ",""),4,4)&"-"&RIGHT(SUBSTITUTE(SUBSTITUTE(D4,"-","")," ",""),4) | L4: =TRIM(MID(SUBSTITUTE(TRIM(E4)," ",REPT(" ",50)),51,50)) | M4: =SUBSTITUTE(F4," ","") | N4: =TRIM(H4) | O4: =IF(I4="",설정!$B$2-J4,I4-J4) | P4: =IF(O4>14,IF(N4="처리중","기한초과","지연처리"),"")
A5: 2026-0003 | B5: 2026.09.24 | C5: 안현우 | D5: 010 9690 1508 | E5: 대구광역시 중구 침산동 822-25 | F5: 건축과 | G5: 건축허가 처리 문의 | H5: 완료 | I5: 46302 | J5: =IF(ISNUMBER(B5),B5,DATE(VALUE(LEFT(B5,4)),VALUE(MID(B5,6,2)),VALUE(RIGHT(B5,2)))) | K5: =LEFT(SUBSTITUTE(SUBSTITUTE(D5,"-","")," ",""),3)&"-"&MID(SUBSTITUTE(SUBSTITUTE(D5,"-","")," ",""),4,4)&"-"&RIGHT(SUBSTITUTE(SUBSTITUTE(D5,"-","")," ",""),4) | L5: =TRIM(MID(SUBSTITUTE(TRIM(E5)," ",REPT(" ",50)),51,50)) | M5: =SUBSTITUTE(F5," ","") | N5: =TRIM(H5) | O5: =IF(I5="",설정!$B$2-J5,I5-J5) | P5: =IF(O5>14,IF(N5="처리중","기한초과","지연처리"),"")
A6: 2026-0004 | B6: 46302 | C6: 황정훈 | D6: 010 4731 3932 | E6: 대구광역시 서구 침산동 909-22 | F6: 건축과 | G6: 불법 건축물 신고 | H6: 완료 | I6: 46303 | J6: =IF(ISNUMBER(B6),B6,DATE(VALUE(LEFT(B6,4)),VALUE(MID(B6,6,2)),VALUE(RIGHT(B6,2)))) | K6: =LEFT(SUBSTITUTE(SUBSTITUTE(D6,"-","")," ",""),3)&"-"&MID(SUBSTITUTE(SUBSTITUTE(D6,"-","")," ",""),4,4)&"-"&RIGHT(SUBSTITUTE(SUBSTITUTE(D6,"-","")," ",""),4) | L6: =TRIM(MID(SUBSTITUTE(TRIM(E6)," ",REPT(" ",50)),51,50)) | M6: =SUBSTITUTE(F6," ","") | N6: =TRIM(H6) | O6: =IF(I6="",설정!$B$2-J6,I6-J6) | P6: =IF(O6>14,IF(N6="처리중","기한초과","지연처리"),"")
A7: 2026-0005 | B7: 2026.09.08 | C7: 서다은 | D7: 010-6368-9519 | E7: 대구광역시 서구 신암동 562-26 | F7: 민원봉사과 | G7: 증명서 발급 문의 | H7: 처리중 | J7: =IF(ISNUMBER(B7),B7,DATE(VALUE(LEFT(B7,4)),VALUE(MID(B7,6,2)),VALUE(RIGHT(B7,2)))) | K7: =LEFT(SUBSTITUTE(SUBSTITUTE(D7,"-","")," ",""),3)&"-"&MID(SUBSTITUTE(SUBSTITUTE(D7,"-","")," ",""),4,4)&"-"&RIGHT(SUBSTITUTE(SUBSTITUTE(D7,"-","")," ",""),4) | L7: =TRIM(MID(SUBSTITUTE(TRIM(E7)," ",REPT(" ",50)),51,50)) | M7: =SUBSTITUTE(F7," ","") | N7: =TRIM(H7) | O7: =IF(I7="",설정!$B$2-J7,I7-J7) | P7: =IF(O7>14,IF(N7="처리중","기한초과","지연처리"),"")
A8: 2026-0006 | B8: 2026.09.19 | C8: 황가영 | D8: 010 9150 2247 | E8: 대구광역시 중구 내당동 944-7 | F8: 복지정책과 | G8: 노인돌봄서비스 신청 문의 | H8: 완료 | I8: 46289 | J8: =IF(ISNUMBER(B8),B8,DATE(VALUE(LEFT(B8,4)),VALUE(MID(B8,6,2)),VALUE(RIGHT(B8,2)))) | K8: =LEFT(SUBSTITUTE(SUBSTITUTE(D8,"-","")," ",""),3)&"-"&MID(SUBSTITUTE(SUBSTITUTE(D8,"-","")," ",""),4,4)&"-"&RIGHT(SUBSTITUTE(SUBSTITUTE(D8,"-","")," ",""),4) | L8: =TRIM(MID(SUBSTITUTE(TRIM(E8)," ",REPT(" ",50)),51,50)) | M8: =SUBSTITUTE(F8," ","") | N8: =TRIM(H8) | O8: =IF(I8="",설정!$B$2-J8,I8-J8) | P8: =IF(O8>14,IF(N8="처리중","기한초과","지연처리"),"")
A9: 2026-0007 | B9: 46301 | C9: 황도윤 | D9: 010-4320-3533 | E9: 대구광역시 서구 침산동 266-15 | F9: 민원봉사과 | G9: 민원실 이용 불편 건의 | H9: 이관 | I9: 46311 | J9: =IF(ISNUMBER(B9),B9,DATE(VALUE(LEFT(B9,4)),VALUE(MID(B9,6,2)),VALUE(RIGHT(B9,2)))) | K9: =LEFT(SUBSTITUTE(SUBSTITUTE(D9,"-","")," ",""),3)&"-"&MID(SUBSTITUTE(SUBSTITUTE(D9,"-","")," ",""),4,4)&"-"&RIGHT(SUBSTITUTE(SUBSTITUTE(D9,"-","")," ",""),4) | L9: =TRIM(MID(SUBSTITUTE(TRIM(E9)," ",REPT(" ",50)),51,50)) | M9: =SUBSTITUTE(F9," ","") | N9: =TRIM(H9) | O9: =IF(I9="",설정!$B$2-J9,I9-J9) | P9: =IF(O9>14,IF(N9="처리중","기한초과","지연처리"),"")
A10: 2026-0008 | B10: 2026.10.02 | C10: 조지우 | D10: 010-4964-3929 | E10: 대구광역시 수성구 상인동 1-15 | F10: 복지정책과 | G10: 기초생활수급 상담 | H10: 완료 | I10: 46321 | J10: =IF(ISNUMBER(B10),B10,DATE(VALUE(LEFT(B10,4)),VALUE(MID(B10,6,2)),VALUE(RIGHT(B10,2)))) | K10: =LEFT(SUBSTITUTE(SUBSTITUTE(D10,"-","")," ",""),3)&"-"&MID(SUBSTITUTE(SUBSTITUTE(D10,"-","")," ",""),4,4)&"-"&RIGHT(SUBSTITUTE(SUBSTITUTE(D10,"-","")," ",""),4) | L10: =TRIM(MID(SUBSTITUTE(TRIM(E10)," ",REPT(" ",50)),51,50)) | M10: =SUBSTITUTE(F10," ","") | N10: =TRIM(H10) | O10: =IF(I10="",설정!$B$2-J10,I10-J10) | P10: =IF(O10>14,IF(N10="처리중","기한초과","지연처리"),"")
A11: 2026-0009 | B11: 2026.10.10 | C11: 정소율 | D11: 01077949368 | E11: 대구광역시 북구 만촌동 589-25 | F11: 도로과 | G11: 도로 파손(포트홀) 신고 | H11: 처리중 | J11: =IF(ISNUMBER(B11),B11,DATE(VALUE(LEFT(B11,4)),VALUE(MID(B11,6,2)),VALUE(RIGHT(B11,2)))) | K11: =LEFT(SUBSTITUTE(SUBSTITUTE(D11,"-","")," ",""),3)&"-"&MID(SUBSTITUTE(SUBSTITUTE(D11,"-","")," ",""),4,4)&"-"&RIGHT(SUBSTITUTE(SUBSTITUTE(D11,"-","")," ",""),4) | L11: =TRIM(MID(SUBSTITUTE(TRIM(E11)," ",REPT(" ",50)),51,50)) | M11: =SUBSTITUTE(F11," ","") | N11: =TRIM(H11) | O11: =IF(I11="",설정!$B$2-J11,I11-J11) | P11: =IF(O11>14,IF(N11="처리중","기한초과","지연처리"),"")
A12: 2026-0010 | B12: 2026.10.01 | C12: 신준서 | D12: 01097742558 | E12: 대구광역시 중구 칠성동 958-5 | F12: 교통행정과 | G12: 불법주정차 신고 | H12: 완료 | I12: 46316 | J12: =IF(ISNUMBER(B12),B12,DATE(VALUE(LEFT(B12,4)),VALUE(MID(B12,6,2)),VALUE(RIGHT(B12,2)))) | K12: =LEFT(SUBSTITUTE(SUBSTITUTE(D12,"-","")," ",""),3)&"-"&MID(SUBSTITUTE(SUBSTITUTE(D12,"-","")," ",""),4,4)&"-"&RIGHT(SUBSTITUTE(SUBSTITUTE(D12,"-","")," ",""),4) | L12: =TRIM(MID(SUBSTITUTE(TRIM(E12)," ",REPT(" ",50)),51,50)) | M12: =SUBSTITUTE(F12," ","") | N12: =TRIM(H12) | O12: =IF(I12="",설정!$B$2-J12,I12-J12) | P12: =IF(O12>14,IF(N12="처리중","기한초과","지연처리"),"")
A13: 2026-0011 | B13: 46299 | C13: 임시우 | D13: 01039856055 | E13: 대구광역시 북구 내당동 957-25 | F13: 환경 위생과 | G13: 악취 발생 민원 | H13: 완료 | I13: 46303 | J13: =IF(ISNUMBER(B13),B13,DATE(VALUE(LEFT(B13,4)),VALUE(MID(B13,6,2)),VALUE(RIGHT(B13,2)))) | K13: =LEFT(SUBSTITUTE(SUBSTITUTE(D13,"-","")," ",""),3)&"-"&MID(SUBSTITUTE(SUBSTITUTE(D13,"-","")," ",""),4,4)&"-"&RIGHT(SUBSTITUTE(SUBSTITUTE(D13,"-","")," ",""),4) | L13: =TRIM(MID(SUBSTITUTE(TRIM(E13)," ",REPT(" ",50)),51,50)) | M13: =SUBSTITUTE(F13," ","") | N13: =TRIM(H13) | O13: =IF(I13="",설정!$B$2-J13,I13-J13) | P13: =IF(O13>14,IF(N13="처리중","기한초과","지연처리"),"")
A14: 2026-0012 | B14: 46273 | C14: 박소율 | D14: 01052915476 | E14: 대구광역시 동구 동성로 445-20 | F14: 건축과 | G14: 건축허가 처리 문의 | H14: 이관 | I14: 46292 | J14: =IF(ISNUMBER(B14),B14,DATE(VALUE(LEFT(B14,4)),VALUE(MID(B14,6,2)),VALUE(RIGHT(B14,2)))) | K14: =LEFT(SUBSTITUTE(SUBSTITUTE(D14,"-","")," ",""),3)&"-"&MID(SUBSTITUTE(SUBSTITUTE(D14,"-","")," ",""),4,4)&"-"&RIGHT(SUBSTITUTE(SUBSTITUTE(D14,"-","")," ",""),4) | L14: =TRIM(MID(SUBSTITUTE(TRIM(E14)," ",REPT(" ",50)),51,50)) | M14: =SUBSTITUTE(F14," ","") | N14: =TRIM(H14) | O14: =IF(I14="",설정!$B$2-J14,I14-J14) | P14: =IF(O14>14,IF(N14="처리중","기한초과","지연처리"),"")
A15: 2026-0014 | B15: 46276 | C15: 신서윤 | D15: 010-8709-0084 | E15: 대구광역시 수성구 대명동 313-6 | F15: 민원봉사과 | G15: 민원실 이용 불편 건의 | H15: 처리중 | J15: =IF(ISNUMBER(B15),B15,DATE(VALUE(LEFT(B15,4)),VALUE(MID(B15,6,2)),VALUE(RIGHT(B15,2)))) | K15: =LEFT(SUBSTITUTE(SUBSTITUTE(D15,"-","")," ",""),3)&"-"&MID(SUBSTITUTE(SUBSTITUTE(D15,"-","")," ",""),4,4)&"-"&RIGHT(SUBSTITUTE(SUBSTITUTE(D15,"-","")," ",""),4) | L15: =TRIM(MID(SUBSTITUTE(TRIM(E15)," ",REPT(" ",50)),51,50)) | M15: =SUBSTITUTE(F15," ","") | N15: =TRIM(H15) | O15: =IF(I15="",설정!$B$2-J15,I15-J15) | P15: =IF(O15>14,IF(N15="처리중","기한초과","지연처리"),"")
A16: 2026-0013 | B16: 46268 | C16: 조가영 | D16: 010-3646-7611 | E16: 대구광역시 서구 동성로 496-23 | F16: 환경 위생과 | G16: 생활쓰레기 무단투기 민원 | H16: 처리중 | J16: =IF(ISNUMBER(B16),B16,DATE(VALUE(LEFT(B16,4)),VALUE(MID(B16,6,2)),VALUE(RIGHT(B16,2)))) | K16: =LEFT(SUBSTITUTE(SUBSTITUTE(D16,"-","")," ",""),3)&"-"&MID(SUBSTITUTE(SUBSTITUTE(D16,"-","")," ",""),4,4)&"-"&RIGHT(SUBSTITUTE(SUBSTITUTE(D16,"-","")," ",""),4) | L16: =TRIM(MID(SUBSTITUTE(TRIM(E16)," ",REPT(" ",50)),51,50)) | M16: =SUBSTITUTE(F16," ","") | N16: =TRIM(H16) | O16: =IF(I16="",설정!$B$2-J16,I16-J16) | P16: =IF(O16>14,IF(N16="처리중","기한초과","지연처리"),"")
A17: 2026-0014 | B17: 46276 | C17: 신서윤 | D17: 010-8709-0084 | E17: 대구광역시 수성구 대명동 313-6 | F17: 민원봉사과 | G17: 민원실 이용 불편 건의 | H17: 처리중 | J17: =IF(ISNUMBER(B17),B17,DATE(VALUE(LEFT(B17,4)),VALUE(MID(B17,6,2)),VALUE(RIGHT(B17,2)))) | K17: =LEFT(SUBSTITUTE(SUBSTITUTE(D17,"-","")," ",""),3)&"-"&MID(SUBSTITUTE(SUBSTITUTE(D17,"-","")," ",""),4,4)&"-"&RIGHT(SUBSTITUTE(SUBSTITUTE(D17,"-","")," ",""),4) | L17: =TRIM(MID(SUBSTITUTE(TRIM(E17)," ",REPT(" ",50)),51,50)) | M17: =SUBSTITUTE(F17," ","") | N17: =TRIM(H17) | O17: =IF(I17="",설정!$B$2-J17,I17-J17) | P17: =IF(O17>14,IF(N17="처리중","기한초과","지연처리"),"")
A18: 2026-0015 | B18: 46277 | C18: 강민준 | D18: 010 6675 3198 | E18: 대구광역시 달서구 동성로 6-3 | F18: 복지정책과 | G18: 노인돌봄서비스 신청 문의 | H18: 완료 | I18: 46292 | J18: =IF(ISNUMBER(B18),B18,DATE(VALUE(LEFT(B18,4)),VALUE(MID(B18,6,2)),VALUE(RIGHT(B18,2)))) | K18: =LEFT(SUBSTITUTE(SUBSTITUTE(D18,"-","")," ",""),3)&"-"&MID(SUBSTITUTE(SUBSTITUTE(D18,"-","")," ",""),4,4)&"-"&RIGHT(SUBSTITUTE(SUBSTITUTE(D18,"-","")," ",""),4) | L18: =TRIM(MID(SUBSTITUTE(TRIM(E18)," ",REPT(" ",50)),51,50)) | M18: =SUBSTITUTE(F18," ","") | N18: =TRIM(H18) | O18: =IF(I18="",설정!$B$2-J18,I18-J18) | P18: =IF(O18>14,IF(N18="처리중","기한초과","지연처리"),"")
A19: 2026-0016 | B19: 2026.09.11 | C19: 장보라 | D19: 01059063835 | E19: 대구광역시 서구 신암동 570-25 | F19: 복지정책과 | G19: 기초생활수급 상담 | H19: 완료 | I19: 46295 | J19: =IF(ISNUMBER(B19),B19,DATE(VALUE(LEFT(B19,4)),VALUE(MID(B19,6,2)),VALUE(RIGHT(B19,2)))) | K19: =LEFT(SUBSTITUTE(SUBSTITUTE(D19,"-","")," ",""),3)&"-"&MID(SUBSTITUTE(SUBSTITUTE(D19,"-","")," ",""),4,4)&"-"&RIGHT(SUBSTITUTE(SUBSTITUTE(D19,"-","")," ",""),4) | L19: =TRIM(MID(SUBSTITUTE(TRIM(E19)," ",REPT(" ",50)),51,50)) | M19: =SUBSTITUTE(F19," ","") | N19: =TRIM(H19) | O19: =IF(I19="",설정!$B$2-J19,I19-J19) | P19: =IF(O19>14,IF(N19="처리중","기한초과","지연처리"),"")
A20: 2026-0017 | B20: 46272 | C20: 박서윤 | D20: 010-3811-0255 | E20: 대구광역시 서구 칠성동 662-21 | F20: 복지정책과 | G20: 노인돌봄서비스 신청 문의 | H20: 완료 | I20: 46286 | J20: =IF(ISNUMBER(B20),B20,DATE(VALUE(LEFT(B20,4)),VALUE(MID(B20,6,2)),VALUE(RIGHT(B20,2)))) | K20: =LEFT(SUBSTITUTE(SUBSTITUTE(D20,"-","")," ",""),3)&"-"&MID(SUBSTITUTE(SUBSTITUTE(D20,"-","")," ",""),4,4)&"-"&RIGHT(SUBSTITUTE(SUBSTITUTE(D20,"-","")," ",""),4) | L20: =TRIM(MID(SUBSTITUTE(TRIM(E20)," ",REPT(" ",50)),51,50)) | M20: =SUBSTITUTE(F20," ","") | N20: =TRIM(H20) | O20: =IF(I20="",설정!$B$2-J20,I20-J20) | P20: =IF(O20>14,IF(N20="처리중","기한초과","지연처리"),"")
A21: 2026-0033 | B21: 46292 | C21: 장지우 | D21: 010-4712-4039 | E21: 대구광역시 북구 상인동 328-9 | F21: 교통행정과 | G21: 버스노선 조정 건의 | H21: 완료 | I21: 46297 | J21: =IF(ISNUMBER(B21),B21,DATE(VALUE(LEFT(B21,4)),VALUE(MID(B21,6,2)),VALUE(RIGHT(B21,2)))) | K21: =LEFT(SUBSTITUTE(SUBSTITUTE(D21,"-","")," ",""),3)&"-"&MID(SUBSTITUTE(SUBSTITUTE(D21,"-","")," ",""),4,4)&"-"&RIGHT(SUBSTITUTE(SUBSTITUTE(D21,"-","")," ",""),4) | L21: =TRIM(MID(SUBSTITUTE(TRIM(E21)," ",REPT(" ",50)),51,50)) | M21: =SUBSTITUTE(F21," ","") | N21: =TRIM(H21) | O21: =IF(I21="",설정!$B$2-J21,I21-J21) | P21: =IF(O21>14,IF(N21="처리중","기한초과","지연처리"),"")
A22: 2026-0018 | B22: 46276 | C22: 류세아 | D22: 010-6449-9597 | E22: 대구광역시 수성구 범어동 99-8 | F22: 복지 정책과 | G22: 노인돌봄서비스 신청 문의 | H22: 완료 | I22: 46277 | J22: =IF(ISNUMBER(B22),B22,DATE(VALUE(LEFT(B22,4)),VALUE(MID(B22,6,2)),VALUE(RIGHT(B22,2)))) | K22: =LEFT(SUBSTITUTE(SUBSTITUTE(D22,"-","")," ",""),3)&"-"&MID(SUBSTITUTE(SUBSTITUTE(D22,"-","")," ",""),4,4)&"-"&RIGHT(SUBSTITUTE(SUBSTITUTE(D22,"-","")," ",""),4) | L22: =TRIM(MID(SUBSTITUTE(TRIM(E22)," ",REPT(" ",50)),51,50)) | M22: =SUBSTITUTE(F22," ","") | N22: =TRIM(H22) | O22: =IF(I22="",설정!$B$2-J22,I22-J22) | P22: =IF(O22>14,IF(N22="처리중","기한초과","지연처리"),"")
A23: 2026-0019 | B23: 2026.09.21 | C23: 오미래 | D23: 010 3510 1730 | E23: 대구광역시 북구 만촌동 221-20 | F23: 건축과 | G23: 건축허가 처리 문의 | H23: 처리중 | J23: =IF(ISNUMBER(B23),B23,DATE(VALUE(LEFT(B23,4)),VALUE(MID(B23,6,2)),VALUE(RIGHT(B23,2)))) | K23: =LEFT(SUBSTITUTE(SUBSTITUTE(D23,"-","")," ",""),3)&"-"&MID(SUBSTITUTE(SUBSTITUTE(D23,"-","")," ",""),4,4)&"-"&RIGHT(SUBSTITUTE(SUBSTITUTE(D23,"-","")," ",""),4) | L23: =TRIM(MID(SUBSTITUTE(TRIM(E23)," ",REPT(" ",50)),51,50)) | M23: =SUBSTITUTE(F23," ","") | N23: =TRIM(H23) | O23: =IF(I23="",설정!$B$2-J23,I23-J23) | P23: =IF(O23>14,IF(N23="처리중","기한초과","지연처리"),"")
A24: 2026-0020 | B24: 46290 | C24: 신건우 | D24: 010 8861 8432 | E24: 대구광역시 북구 내당동 297-24 | F24: 복지정책과 | G24: 기초생활수급 상담 | H24: 이관 | I24: 46302 | J24: =IF(ISNUMBER(B24),B24,DATE(VALUE(LEFT(B24,4)),VALUE(MID(B24,6,2)),VALUE(RIGHT(B24,2)))) | K24: =LEFT(SUBSTITUTE(SUBSTITUTE(D24,"-","")," ",""),3)&"-"&MID(SUBSTITUTE(SUBSTITUTE(D24,"-","")," ",""),4,4)&"-"&RIGHT(SUBSTITUTE(SUBSTITUTE(D24,"-","")," ",""),4) | L24: =TRIM(MID(SUBSTITUTE(TRIM(E24)," ",REPT(" ",50)),51,50)) | M24: =SUBSTITUTE(F24," ","") | N24: =TRIM(H24) | O24: =IF(I24="",설정!$B$2-J24,I24-J24) | P24: =IF(O24>14,IF(N24="처리중","기한초과","지연처리"),"")
A25: 2026-0021 | B25: 2026.10.05 | C25: 신태민 | D25: 01045112594 | E25: 대구광역시 수성구 상인동 39-5 | F25: 복지정책과 | G25: 기초생활수급 상담 | H25: 완료 | I25: 46302 | J25: =IF(ISNUMBER(B25),B25,DATE(VALUE(LEFT(B25,4)),VALUE(MID(B25,6,2)),VALUE(RIGHT(B25,2)))) | K25: =LEFT(SUBSTITUTE(SUBSTITUTE(D25,"-","")," ",""),3)&"-"&MID(SUBSTITUTE(SUBSTITUTE(D25,"-","")," ",""),4,4)&"-"&RIGHT(SUBSTITUTE(SUBSTITUTE(D25,"-","")," ",""),4) | L25: =TRIM(MID(SUBSTITUTE(TRIM(E25)," ",REPT(" ",50)),51,50)) | M25: =SUBSTITUTE(F25," ","") | N25: =TRIM(H25) | O25: =IF(I25="",설정!$B$2-J25,I25-J25) | P25: =IF(O25>14,IF(N25="처리중","기한초과","지연처리"),"")
A26: 2026-0055 | B26: 46303 | C26: 오도윤 | D26: 010 4490 6099 | E26: 대구광역시 중구 대명동 6-8 | F26: 도로과 | G26: 가로등 고장 신고 | H26: 완료 | I26: 46318 | J26: =IF(ISNUMBER(B26),B26,DATE(VALUE(LEFT(B26,4)),VALUE(MID(B26,6,2)),VALUE(RIGHT(B26,2)))) | K26: =LEFT(SUBSTITUTE(SUBSTITUTE(D26,"-","")," ",""),3)&"-"&MID(SUBSTITUTE(SUBSTITUTE(D26,"-","")," ",""),4,4)&"-"&RIGHT(SUBSTITUTE(SUBSTITUTE(D26,"-","")," ",""),4) | L26: =TRIM(MID(SUBSTITUTE(TRIM(E26)," ",REPT(" ",50)),51,50)) | M26: =SUBSTITUTE(F26," ","") | N26: =TRIM(H26) | O26: =IF(I26="",설정!$B$2-J26,I26-J26) | P26: =IF(O26>14,IF(N26="처리중","기한초과","지연처리"),"")
A27: 2026-0022 | B27: 2026.09.23 | C27: 장가영 | D27: 010-5946-9554 | E27: 대구광역시 달서구 침산동 30-22 | F27: 건축과 | G27: 불법 건축물 신고 | H27: 완료 | I27: 46296 | J27: =IF(ISNUMBER(B27),B27,DATE(VALUE(LEFT(B27,4)),VALUE(MID(B27,6,2)),VALUE(RIGHT(B27,2)))) | K27: =LEFT(SUBSTITUTE(SUBSTITUTE(D27,"-","")," ",""),3)&"-"&MID(SUBSTITUTE(SUBSTITUTE(D27,"-","")," ",""),4,4)&"-"&RIGHT(SUBSTITUTE(SUBSTITUTE(D27,"-","")," ",""),4) | L27: =TRIM(MID(SUBSTITUTE(TRIM(E27)," ",REPT(" ",50)),51,50)) | M27: =SUBSTITUTE(F27," ","") | N27: =TRIM(H27) | O27: =IF(I27="",설정!$B$2-J27,I27-J27) | P27: =IF(O27>14,IF(N27="처리중","기한초과","지연처리"),"")
A28: 2026-0023 | B28: 46280 | C28: 안동현 | D28: 010 6540 8799 | E28: 대구광역시 달서구 만촌동 92-27 | F28: 도로 과 | G28: 가로등 고장 신고 | H28: 완료 | I28: 46298 | J28: =IF(ISNUMBER(B28),B28,DATE(VALUE(LEFT(B28,4)),VALUE(MID(B28,6,2)),VALUE(RIGHT(B28,2)))) | K28: =LEFT(SUBSTITUTE(SUBSTITUTE(D28,"-","")," ",""),3)&"-"&MID(SUBSTITUTE(SUBSTITUTE(D28,"-","")," ",""),4,4)&"-"&RIGHT(SUBSTITUTE(SUBSTITUTE(D28,"-","")," ",""),4) | L28: =TRIM(MID(SUBSTITUTE(TRIM(E28)," ",REPT(" ",50)),51,50)) | M28: =SUBSTITUTE(F28," ","") | N28: =TRIM(H28) | O28: =IF(I28="",설정!$B$2-J28,I28-J28) | P28: =IF(O28>14,IF(N28="처리중","기한초과","지연처리"),"")
A29: 2026-0024 | B29: 46287 | C29: 서재현 | D29: 010-3153-1334 | E29: 대구광역시 달서구 지산동 60-8 | F29: 민원봉사과 | G29: 민원실 이용 불편 건의 | H29: 완료 | I29: 46311 | J29: =IF(ISNUMBER(B29),B29,DATE(VALUE(LEFT(B29,4)),VALUE(MID(B29,6,2)),VALUE(RIGHT(B29,2)))) | K29: =LEFT(SUBSTITUTE(SUBSTITUTE(D29,"-","")," ",""),3)&"-"&MID(SUBSTITUTE(SUBSTITUTE(D29,"-","")," ",""),4,4)&"-"&RIGHT(SUBSTITUTE(SUBSTITUTE(D29,"-","")," ",""),4) | L29: =TRIM(MID(SUBSTITUTE(TRIM(E29)," ",REPT(" ",50)),51,50)) | M29: =SUBSTITUTE(F29," ","") | N29: =TRIM(H29) | O29: =IF(I29="",설정!$B$2-J29,I29-J29) | P29: =IF(O29>14,IF(N29="처리중","기한초과","지연처리"),"")
A30: 2026-0045 | B30: 46300 | C30: 장건우 | D30: 01073554102 | E30: 대구광역시 동구 범어동 483-1 | F30: 도로과 | G30: 도로 파손(포트홀) 신고 | H30: 완료 | I30: 46324 | J30: =IF(ISNUMBER(B30),B30,DATE(VALUE(LEFT(B30,4)),VALUE(MID(B30,6,2)),VALUE(RIGHT(B30,2)))) | K30: =LEFT(SUBSTITUTE(SUBSTITUTE(D30,"-","")," ",""),3)&"-"&MID(SUBSTITUTE(SUBSTITUTE(D30,"-","")," ",""),4,4)&"-"&RIGHT(SUBSTITUTE(SUBSTITUTE(D30,"-","")," ",""),4) | L30: =TRIM(MID(SUBSTITUTE(TRIM(E30)," ",REPT(" ",50)),51,50)) | M30: =SUBSTITUTE(F30," ","") | N30: =TRIM(H30) | O30: =IF(I30="",설정!$B$2-J30,I30-J30) | P30: =IF(O30>14,IF(N30="처리중","기한초과","지연처리"),"")
A31: 2026-0025 | B31: 46280 | C31: 조수아 | D31: 01056974998 | E31: 대구광역시 중구 지산동 562-26 | F31: 교통행정과 | G31: 버스노선 조정 건의 | H31: 처리중 | J31: =IF(ISNUMBER(B31),B31,DATE(VALUE(LEFT(B31,4)),VALUE(MID(B31,6,2)),VALUE(RIGHT(B31,2)))) | K31: =LEFT(SUBSTITUTE(SUBSTITUTE(D31,"-","")," ",""),3)&"-"&MID(SUBSTITUTE(SUBSTITUTE(D31,"-","")," ",""),4,4)&"-"&RIGHT(SUBSTITUTE(SUBSTITUTE(D31,"-","")," ",""),4) | L31: =TRIM(MID(SUBSTITUTE(TRIM(E31)," ",REPT(" ",50)),51,50)) | M31: =SUBSTITUTE(F31," ","") | N31: =TRIM(H31) | O31: =IF(I31="",설정!$B$2-J31,I31-J31) | P31: =IF(O31>14,IF(N31="처리중","기한초과","지연처리"),"")
A32: 2026-0026 | B32: 2026.09.10 | C32: 최정훈 | D32: 010-8480-4706 | E32: 대구광역시 서구 칠성동 87-10 | F32: 건축과 | G32: 불법 건축물 신고 | H32: 처리중 | J32: =IF(ISNUMBER(B32),B32,DATE(VALUE(LEFT(B32,4)),VALUE(MID(B32,6,2)),VALUE(RIGHT(B32,2)))) | K32: =LEFT(SUBSTITUTE(SUBSTITUTE(D32,"-","")," ",""),3)&"-"&MID(SUBSTITUTE(SUBSTITUTE(D32,"-","")," ",""),4,4)&"-"&RIGHT(SUBSTITUTE(SUBSTITUTE(D32,"-","")," ",""),4) | L32: =TRIM(MID(SUBSTITUTE(TRIM(E32)," ",REPT(" ",50)),51,50)) | M32: =SUBSTITUTE(F32," ","") | N32: =TRIM(H32) | O32: =IF(I32="",설정!$B$2-J32,I32-J32) | P32: =IF(O32>14,IF(N32="처리중","기한초과","지연처리"),"")
A33: 2026-0027 | B33: 2026.10.05 | C33: 최도윤 | D33: 010-7116-5991 | E33: 대구광역시 중구 대명동 552-17 | F33: 환경위생과 | G33: 생활쓰레기 무단투기 민원 | H33: 처리중 | J33: =IF(ISNUMBER(B33),B33,DATE(VALUE(LEFT(B33,4)),VALUE(MID(B33,6,2)),VALUE(RIGHT(B33,2)))) | K33: =LEFT(SUBSTITUTE(SUBSTITUTE(D33,"-","")," ",""),3)&"-"&MID(SUBSTITUTE(SUBSTITUTE(D33,"-","")," ",""),4,4)&"-"&RIGHT(SUBSTITUTE(SUBSTITUTE(D33,"-","")," ",""),4) | L33: =TRIM(MID(SUBSTITUTE(TRIM(E33)," ",REPT(" ",50)),51,50)) | M33: =SUBSTITUTE(F33," ","") | N33: =TRIM(H33) | O33: =IF(I33="",설정!$B$2-J33,I33-J33) | P33: =IF(O33>14,IF(N33="처리중","기한초과","지연처리"),"")
A34: 2026-0028 | B34: 46312 | C34: 김미래 | D34: 01055471405 | E34: 대구광역시 북구 신암동 555-10 | F34: 건축과 | G34: 건축허가 처리 문의 | H34: 완료 | I34: 46321 | J34: =IF(ISNUMBER(B34),B34,DATE(VALUE(LEFT(B34,4)),VALUE(MID(B34,6,2)),VALUE(RIGHT(B34,2)))) | K34: =LEFT(SUBSTITUTE(SUBSTITUTE(D34,"-","")," ",""),3)&"-"&MID(SUBSTITUTE(SUBSTITUTE(D34,"-","")," ",""),4,4)&"-"&RIGHT(SUBSTITUTE(SUBSTITUTE(D34,"-","")," ",""),4) | L34: =TRIM(MID(SUBSTITUTE(TRIM(E34)," ",REPT(" ",50)),51,50)) | M34: =SUBSTITUTE(F34," ","") | N34: =TRIM(H34) | O34: =IF(I34="",설정!$B$2-J34,I34-J34) | P34: =IF(O34>14,IF(N34="처리중","기한초과","지연처리"),"")
A35: 2026-0029 | B35: 2026.09.28 | C35: 김동현 | D35: 010-5293-5827 | E35: 대구광역시 수성구 칠성동 323-18 | F35: 복지 정책과 | G35: 노인돌봄서비스 신청 문의 | H35: 처리중 | J35: =IF(ISNUMBER(B35),B35,DATE(VALUE(LEFT(B35,4)),VALUE(MID(B35,6,2)),VALUE(RIGHT(B35,2)))) | K35: =LEFT(SUBSTITUTE(SUBSTITUTE(D35,"-","")," ",""),3)&"-"&MID(SUBSTITUTE(SUBSTITUTE(D35,"-","")," ",""),4,4)&"-"&RIGHT(SUBSTITUTE(SUBSTITUTE(D35,"-","")," ",""),4) | L35: =TRIM(MID(SUBSTITUTE(TRIM(E35)," ",REPT(" ",50)),51,50)) | M35: =SUBSTITUTE(F35," ","") | N35: =TRIM(H35) | O35: =IF(I35="",설정!$B$2-J35,I35-J35) | P35: =IF(O35>14,IF(N35="처리중","기한초과","지연처리"),"")
A36: 2026-0030 | B36: 46270 | C36: 임승현 | D36: 01063306810 | E36: 대구광역시 북구 지산동 110-28 | F36: 복지 정책과 | G36: 기초생활수급 상담 | H36: 완료 | I36: 46288 | J36: =IF(ISNUMBER(B36),B36,DATE(VALUE(LEFT(B36,4)),VALUE(MID(B36,6,2)),VALUE(RIGHT(B36,2)))) | K36: =LEFT(SUBSTITUTE(SUBSTITUTE(D36,"-","")," ",""),3)&"-"&MID(SUBSTITUTE(SUBSTITUTE(D36,"-","")," ",""),4,4)&"-"&RIGHT(SUBSTITUTE(SUBSTITUTE(D36,"-","")," ",""),4) | L36: =TRIM(MID(SUBSTITUTE(TRIM(E36)," ",REPT(" ",50)),51,50)) | M36: =SUBSTITUTE(F36," ","") | N36: =TRIM(H36) | O36: =IF(I36="",설정!$B$2-J36,I36-J36) | P36: =IF(O36>14,IF(N36="처리중","기한초과","지연처리"),"")
A37: 2026-0032 | B37: 46282 | C37: 오성민 | D37: 01074521716 | E37: 대구광역시 서구 지산동 413-11 | F37: 민원봉사과 | G37: 민원실 이용 불편 건의 | H37: 완료 | I37: 46293 | J37: =IF(ISNUMBER(B37),B37,DATE(VALUE(LEFT(B37,4)),VALUE(MID(B37,6,2)),VALUE(RIGHT(B37,2)))) | K37: =LEFT(SUBSTITUTE(SUBSTITUTE(D37,"-","")," ",""),3)&"-"&MID(SUBSTITUTE(SUBSTITUTE(D37,"-","")," ",""),4,4)&"-"&RIGHT(SUBSTITUTE(SUBSTITUTE(D37,"-","")," ",""),4) | L37: =TRIM(MID(SUBSTITUTE(TRIM(E37)," ",REPT(" ",50)),51,50)) | M37: =SUBSTITUTE(F37," ","") | N37: =TRIM(H37) | O37: =IF(I37="",설정!$B$2-J37,I37-J37) | P37: =IF(O37>14,IF(N37="처리중","기한초과","지연처리"),"")
A38: 2026-0031 | B38: 46288 | C38: 황성민 | D38: 010 6315 5381 | E38: 대구광역시 서구 지산동 940-19 | F38: 건축 과 | G38: 건축허가 처리 문의 | H38: 이관 | I38: 46292 | J38: =IF(ISNUMBER(B38),B38,DATE(VALUE(LEFT(B38,4)),VALUE(MID(B38,6,2)),VALUE(RIGHT(B38,2)))) | K38: =LEFT(SUBSTITUTE(SUBSTITUTE(D38,"-","")," ",""),3)&"-"&MID(SUBSTITUTE(SUBSTITUTE(D38,"-","")," ",""),4,4)&"-"&RIGHT(SUBSTITUTE(SUBSTITUTE(D38,"-","")," ",""),4) | L38: =TRIM(MID(SUBSTITUTE(TRIM(E38)," ",REPT(" ",50)),51,50)) | M38: =SUBSTITUTE(F38," ","") | N38: =TRIM(H38) | O38: =IF(I38="",설정!$B$2-J38,I38-J38) | P38: =IF(O38>14,IF(N38="처리중","기한초과","지연처리"),"")
A39: 2026-0032 | B39: 46282 | C39: 오성민 | D39: 01074521716 | E39: 대구광역시 서구 지산동 413-11 | F39: 민원봉사과 | G39: 민원실 이용 불편 건의 | H39: 완료 | I39: 46293 | J39: =IF(ISNUMBER(B39),B39,DATE(VALUE(LEFT(B39,4)),VALUE(MID(B39,6,2)),VALUE(RIGHT(B39,2)))) | K39: =LEFT(SUBSTITUTE(SUBSTITUTE(D39,"-","")," ",""),3)&"-"&MID(SUBSTITUTE(SUBSTITUTE(D39,"-","")," ",""),4,4)&"-"&RIGHT(SUBSTITUTE(SUBSTITUTE(D39,"-","")," ",""),4) | L39: =TRIM(MID(SUBSTITUTE(TRIM(E39)," ",REPT(" ",50)),51,50)) | M39: =SUBSTITUTE(F39," ","") | N39: =TRIM(H39) | O39: =IF(I39="",설정!$B$2-J39,I39-J39) | P39: =IF(O39>14,IF(N39="처리중","기한초과","지연처리"),"")
A40: 2026-0033 | B40: 46292 | C40: 장지우 | D40: 010-4712-4039 | E40: 대구광역시 북구 상인동 328-9 | F40: 교통행정과 | G40: 버스노선 조정 건의 | H40: 완료 | I40: 46297 | J40: =IF(ISNUMBER(B40),B40,DATE(VALUE(LEFT(B40,4)),VALUE(MID(B40,6,2)),VALUE(RIGHT(B40,2)))) | K40: =LEFT(SUBSTITUTE(SUBSTITUTE(D40,"-","")," ",""),3)&"-"&MID(SUBSTITUTE(SUBSTITUTE(D40,"-","")," ",""),4,4)&"-"&RIGHT(SUBSTITUTE(SUBSTITUTE(D40,"-","")," ",""),4) | L40: =TRIM(MID(SUBSTITUTE(TRIM(E40)," ",REPT(" ",50)),51,50)) | M40: =SUBSTITUTE(F40," ","") | N40: =TRIM(H40) | O40: =IF(I40="",설정!$B$2-J40,I40-J40) | P40: =IF(O40>14,IF(N40="처리중","기한초과","지연처리"),"")
...

Sheet 설정
A1: 항목 | B1: 값
A2: 기준일 | B2: 46326
A3: 안내 | B3: 수업 당일에는 B2를 =TODAY() 로 바꿔 보세요. 결과가 달라지는 이유를 AI에게 설명시켜 봅니다.
